<?xml version="1.0" encoding="utf-8"?>
<!-- This URDF was automatically created by SolidWorks to URDF Exporter! Originally created by Stephen Brawner (brawner@gmail.com) 
     Commit Version: 1.6.0-4-g7f85cfe  Build Version: 1.6.7995.38578
     For more information, please see http://wiki.ros.org/sw_urdf_exporter -->
<robot
  name="auto_tractor">
  <link
    name="base_link">
    <inertial>
      <origin
        xyz="-0.39771 -0.028882 -0.025607"
        rpy="0 0 0" />
      <mass
        value="2890" />
      <inertia
        ixx="1.6045"
        ixy="-0.017928"
        ixz="0.049063"
        iyy="2.1845"
        iyz="-0.31498"
        izz="2.9565" />
    </inertial>
    <visual>
      <origin
        xyz="0 0 0"
        rpy="0 0 0" />
      <geometry>
        <mesh
          filename="package://auto_tractor/meshes/base_link.STL" />
      </geometry>
      <material
        name="">
        <color
          rgba="0.79216 0.81961 0.93333 1" />
      </material>
    </visual>
    <collision>
      <origin
        xyz="0 0 0"
        rpy="0 0 0" />
      <geometry>
        <mesh
          filename="package://auto_tractor/meshes/base_link.STL" />
      </geometry>
    </collision>
  </link>
  <link
    name="Front_left">
    <inertial>
      <origin
        xyz="3.1563E-05 0.00069008 1.9321E-05"
        rpy="0 0 0" />
      <mass
        value="100" />
      <inertia
        ixx="8.5259E-05"
        ixy="5.3135E-07"
        ixz="1.3914E-08"
        iyy="1.6562E-05"
        iyz="-1.799E-06"
        izz="8.5216E-05" />
    </inertial>
    <visual>
      <origin
        xyz="0 0 0"
        rpy="0 0 0" />
      <geometry>
        <mesh
          filename="package://auto_tractor/meshes/Front_left.STL" />
      </geometry>
      <material
        name="">
        <color
          rgba="0.4 0.4 0.4 1" />
      </material>
    </visual>
    <collision>
      <origin
        xyz="0 0 0"
        rpy="0 0 0" />
      <geometry>
        <mesh
          filename="package://auto_tractor/meshes/Front_left.STL" />
      </geometry>
    </collision>
  </link>
  <joint
    name="FL"
    type="continuous">
    <origin
      xyz="0.92099 -0.63407 -0.53606"
      rpy="0.34375 0 0" />
    <parent
      link="base_link" />
    <child
      link="Front_left" />
    <axis
      xyz="0 1 0" />
  </joint>
  <link
    name="Front_right">
    <inertial>
      <origin
        xyz="-6.8775E-05 -0.00066764 -4.8204E-05"
        rpy="0 0 0" />
      <mass
        value="100" />
      <inertia
        ixx="8.5259E-05"
        ixy="-5.3135E-07"
        ixz="1.3914E-08"
        iyy="1.6562E-05"
        iyz="1.799E-06"
        izz="8.5216E-05" />
    </inertial>
    <visual>
      <origin
        xyz="0 0 0"
        rpy="0 0 0" />
      <geometry>
        <mesh
          filename="package://auto_tractor/meshes/Front_right.STL" />
      </geometry>
      <material
        name="">
        <color
          rgba="0.4 0.4 0.4 1" />
      </material>
    </visual>
    <collision>
      <origin
        xyz="0 0 0"
        rpy="0 0 0" />
      <geometry>
        <mesh
          filename="package://auto_tractor/meshes/Front_right.STL" />
      </geometry>
    </collision>
  </link>
  <joint
    name="FR"
    type="continuous">
    <origin
      xyz="0.92109 0.83018 -0.011833"
      rpy="0.34375 0 0" />
    <parent
      link="base_link" />
    <child
      link="Front_right" />
    <axis
      xyz="0 1 0" />
  </joint>
  <link
    name="Rear_left">
    <inertial>
      <origin
        xyz="8.3356E-05 0.093454 -0.00017878"
        rpy="0 0 0" />
      <mass
        value="100" />
      <inertia
        ixx="0.00015156"
        ixy="2.284E-09"
        ixz="1.9499E-14"
        iyy="1.8396E-05"
        iyz="-1.137E-09"
        izz="0.00015156" />
    </inertial>
    <visual>
      <origin
        xyz="0 0 0"
        rpy="0 0 0" />
      <geometry>
        <mesh
          filename="package://auto_tractor/meshes/Rear_left.STL" />
      </geometry>
      <material
        name="">
        <color
          rgba="0.2 0.6 0.2 1" />
      </material>
    </visual>
    <collision>
      <origin
        xyz="0 0 0"
        rpy="0 0 0" />
      <geometry>
        <mesh
          filename="package://auto_tractor/meshes/Rear_left.STL" />
      </geometry>
    </collision>
  </link>
  <joint
    name="RL"
    type="continuous">
    <origin
      xyz="-1.3428 -0.81744 -0.40911"
      rpy="0.34375 0 0" />
    <parent
      link="base_link" />
    <child
      link="Rear_left" />
    <axis
      xyz="0 1 0" />
  </joint>
  <link
    name="Rear_right">
    <inertial>
      <origin
        xyz="3.3321E-05 -0.020028 -1.895E-05"
        rpy="0 0 0" />
      <mass
        value="100" />
      <inertia
        ixx="0.00015156"
        ixy="-1.2411E-13"
        ixz="8.4972E-20"
        iyy="1.8396E-05"
        iyz="3.1117E-17"
        izz="0.00015156" />
    </inertial>
    <visual>
      <origin
        xyz="0 0 0"
        rpy="0 0 0" />
      <geometry>
        <mesh
          filename="package://auto_tractor/meshes/Rear_right.STL" />
      </geometry>
      <material
        name="">
        <color
          rgba="0.2 0.6 0.2 1" />
      </material>
    </visual>
    <collision>
      <origin
        xyz="0 0 0"
        rpy="0 0 0" />
      <geometry>
        <mesh
          filename="package://auto_tractor/meshes/Rear_right.STL" />
      </geometry>
    </collision>
  </link>
  <joint
    name="RR"
    type="continuous">
    <origin
      xyz="-1.3428 0.8161 0.17548"
      rpy="0.34375 -0.00020469 -7.3256E-05" />
    <parent
      link="base_link" />
    <child
      link="Rear_right" />
    <axis
      xyz="0 1 0" />
  </joint>
</robot>