<?xml version="1.0" encoding="utf-8"?>
<!-- This URDF was automatically created by SolidWorks to URDF Exporter! Originally created by Stephen Brawner (brawner@gmail.com) 
     Commit Version: 1.6.0-4-g7f85cfe  Build Version: 1.6.7995.38578
     For more information, please see http://wiki.ros.org/sw_urdf_exporter -->
<robot
  name="auto_tractor">
  <link
    name="base_link">
    <inertial>
      <origin
        xyz="-0.397673090685542 -0.0362426035099022 -0.0142888088381169"
        rpy="0 0 0" />
      <mass
        value="58.1363480593461" />
      <inertia
        ixx="1.60457454365589"
        ixy="-0.000838293883199679"
        ixz="0.0525512729594227"
        iyy="2.07226627002833"
        iyz="0.00160779512646578"
        izz="3.0686989437607" />
    </inertial>
    <visual>
      <origin
        xyz="0 0 0"
        rpy="0 0 0" />
      <geometry>
        <mesh
          filename="package://auto_tractor/meshes/base_link.STL" />
      </geometry>
      <material
        name="">
        <color
          rgba="0.792156862745098 0.819607843137255 0.933333333333333 1" />
      </material>
    </visual>
    <collision>
      <origin
        xyz="0 0 0"
        rpy="0 0 0" />
      <geometry>
        <mesh
          filename="package://auto_tractor/meshes/base_link.STL" />
      </geometry>
    </collision>
  </link>
  <link
    name="Front_left">
    <inertial>
      <origin
        xyz="1.88378345540308E-05 0.00212425765837199 5.321682341064E-05"
        rpy="0 0 0" />
      <mass
        value="0.208066209258392" />
      <inertia
        ixx="8.52576630723236E-05"
        ixy="6.03993916269484E-07"
        ixz="1.58162695683191E-08"
        iyy="1.65629960634174E-05"
        iyz="-1.79898799130545E-06"
        izz="8.52158646792167E-05" />
    </inertial>
    <visual>
      <origin
        xyz="0 0 0"
        rpy="0 0 0" />
      <geometry>
        <mesh
          filename="package://auto_tractor/meshes/Front_left.STL" />
      </geometry>
      <material
        name="">
        <color
          rgba="0.4 0.4 0.4 1" />
      </material>
    </visual>
    <collision>
      <origin
        xyz="0 0 0"
        rpy="0 0 0" />
      <geometry>
        <mesh
          filename="package://auto_tractor/meshes/Front_left.STL" />
      </geometry>
    </collision>
  </link>
  <joint
    name="FL"
    type="continuous">
    <origin
      xyz="0.92175 -0.77667 -0.2912"
      rpy="0 0.00021738 0" />
    <parent
      link="base_link" />
    <child
      link="Front_left" />
    <axis
      xyz="0.0066741 0.99964 -0.026176" />
  </joint>
  <link
    name="Front_right">
    <inertial>
      <origin
        xyz="-0.00210169584541864 7.98662894221369E-05 -1.06523957832394E-05"
        rpy="0 0 0" />
      <mass
        value="0.208066209260515" />
      <inertia
        ixx="1.65617954186265E-05"
        ixy="5.31346124129393E-07"
        ixz="1.79900370420684E-06"
        iyy="8.52588637317677E-05"
        iyz="-1.39137857252096E-08"
        izz="8.52158646872661E-05" />
    </inertial>
    <visual>
      <origin
        xyz="0 0 0"
        rpy="0 0 0" />
      <geometry>
        <mesh
          filename="package://auto_tractor/meshes/Front_right.STL" />
      </geometry>
      <material
        name="">
        <color
          rgba="0.4 0.4 0.4 1" />
      </material>
    </visual>
    <collision>
      <origin
        xyz="0 0 0"
        rpy="0 0 0" />
      <geometry>
        <mesh
          filename="package://auto_tractor/meshes/Front_right.STL" />
      </geometry>
    </collision>
  </link>
  <joint
    name="FR"
    type="continuous">
    <origin
      xyz="0.92021 0.7786 -0.29113"
      rpy="0.040824 -0.00030073 1.5708" />
    <parent
      link="base_link" />
    <child
      link="Front_right" />
    <axis
      xyz="0.99963 -0.0077313 -0.026176" />
  </joint>
  <link
    name="Rear_left">
    <inertial>
      <origin
        xyz="4.47265873781411E-05 0.0942501504337356 -0.000134636015207579"
        rpy="0 0 0" />
      <mass
        value="0.245765324492604" />
      <inertia
        ixx="0.000151557898242509"
        ixy="1.42939930925174E-07"
        ixz="3.05132929454485E-13"
        iyy="1.83956887769544E-05"
        iyz="-2.84145388814401E-10"
        izz="0.000151558051676904" />
    </inertial>
    <visual>
      <origin
        xyz="0 0 0"
        rpy="0 0 0" />
      <geometry>
        <mesh
          filename="package://auto_tractor/meshes/Rear_left.STL" />
      </geometry>
      <material
        name="">
        <color
          rgba="0.2 0.6 0.2 1" />
      </material>
    </visual>
    <collision>
      <origin
        xyz="0 0 0"
        rpy="0 0 0" />
      <geometry>
        <mesh
          filename="package://auto_tractor/meshes/Rear_left.STL" />
      </geometry>
    </collision>
  </link>
  <joint
    name="RL"
    type="continuous">
    <origin
      xyz="-1.3419 -0.90892 -0.10944"
      rpy="0 0.00021738 0" />
    <parent
      link="base_link" />
    <child
      link="Rear_left" />
    <axis
      xyz="-0.0010575 1 0" />
  </joint>
  <link
    name="Rear_right">
    <inertial>
      <origin
        xyz="5.84858169907498E-05 -0.0193884390946522 -5.12975625155399E-06"
        rpy="0 0 0" />
      <mass
        value="0.245765324492615" />
      <inertia
        ixx="0.000151557902849104"
        ixy="1.40777840443593E-07"
        ixz="1.11238699718692E-16"
        iyy="1.83956841697627E-05"
        iyz="1.16530187182955E-15"
        izz="0.000151558051677512" />
    </inertial>
    <visual>
      <origin
        xyz="0 0 0"
        rpy="0 0 0" />
      <geometry>
        <mesh
          filename="package://auto_tractor/meshes/Rear_right.STL" />
      </geometry>
      <material
        name="">
        <color
          rgba="0.2 0.6 0.2 1" />
      </material>
    </visual>
    <collision>
      <origin
        xyz="0 0 0"
        rpy="0 0 0" />
      <geometry>
        <mesh
          filename="package://auto_tractor/meshes/Rear_right.STL" />
      </geometry>
    </collision>
  </link>
  <joint
    name="RR"
    type="continuous">
    <origin
      xyz="-1.3437 0.82608 -0.10955"
      rpy="0 0 0" />
    <parent
      link="base_link" />
    <child
      link="Rear_right" />
    <axis
      xyz="-0.0010572 1 0" />
  </joint>
</robot>
