<?xml version="1.0" encoding="utf-8"?>
<!-- This URDF was automatically created by SolidWorks to URDF Exporter! Originally created by Stephen Brawner (brawner@gmail.com) 
     Commit Version: 1.6.0-4-g7f85cfe  Build Version: 1.6.7995.38578
     For more information, please see http://wiki.ros.org/sw_urdf_exporter -->
<robot
  name="auto_tractor">
  <link
    name="base_link">
    <inertial>
      <origin
        xyz="0 0 0"
        rpy="0 0 0" />
      <mass
        value="578" />
      <inertia
        ixx="145.63"
        ixy="-71.36"
        ixz="26.86"
        iyy="776.5"
        iyz="5.58"
        izz="810.32" />
    </inertial>
    <visual>
      <origin
        xyz="0 0 0"
        rpy="0 0 0" />
      <geometry>
        <mesh
          filename="package://auto_tractor/meshes/base_link.STL" />
      </geometry>
      <material
        name="">
        <color
          rgba="0.792156862745098 0.819607843137255 0.933333333333333 1" />
      </material>
    </visual>
    <collision>
      <origin
        xyz="0 0 0"
        rpy="0 0 0" />
      <geometry>
        <mesh
          filename="package://auto_tractor/meshes/base_link.STL" />
      </geometry>
    </collision>
  </link>

<!-- Front Left Wheel -->

  <link
    name="Front_left">
    <inertial>
      <origin
        xyz="0 0 0"
        rpy="0 0 0" />
      <mass
        value="578" />
      <inertia
        ixx="145.63"
        ixy="-71.36"
        ixz="26.86"
        iyy="776.5"
        iyz="5.58"
        izz="810.32" />
    </inertial>
    <visual>
      <origin
        xyz="0 0 0"
        rpy="0 0 0" />
      <geometry>
        <mesh
          filename="package://auto_tractor/meshes/Front_left.STL" />
      </geometry>
      <material
        name="">
        <color
          rgba="0 0 0 1" />
      </material>
    </visual>
    <collision>
      <origin
        xyz="0 0 0"
        rpy="0 0 0" />
      <geometry>
        <mesh
          filename="package://auto_tractor/meshes/Front_left.STL" />
      </geometry>
    </collision>
  </link>

  <joint
    name="FL"
    type="continuous">
    <origin
      xyz="0 0 0"
      rpy="-0.05236 0 0" />
    <parent
      link="front_left_steering_link" />
    <child
      link="Front_left" />
    <axis
      xyz="0 1 0"/>
  </joint>

<!-- Front Right Wheel -->

  <link
    name="Front_right">
    <inertial>
      <origin
        xyz="0 0 0"
        rpy="0 0 0" />
      <mass
        value="578" />
      <inertia
        ixx="145.63"
        ixy="-71.36"
        ixz="26.86"
        iyy="776.5"
        iyz="5.58"
        izz="810.32" />
    </inertial>
    <visual>
      <origin
        xyz="0 0 0"
        rpy="0 0 0" />
      <geometry>
        <mesh
          filename="package://auto_tractor/meshes/Front_right.STL" />
      </geometry>
      <material
        name="">
        <color
          rgba="0.4 0.4 0.4 1" />
      </material>
    </visual>
    <collision>
      <origin
        xyz="0 0 0"
        rpy="0 0 0" />
      <geometry>
        <mesh
          filename="package://auto_tractor/meshes/Front_right.STL" />
      </geometry>
    </collision>
  </link>

  <joint
    name="FR"
    type="continuous">
    <origin
      xyz="0 0 0"
      rpy="0.05236 0 0" />
    <parent
      link="front_right_steering_link" />
    <child
      link="Front_right" />
    <axis
      xyz="0 1 0"/>
  </joint>

  <!-- Rear Left Wheel -->
  <link
    name="Rear_left">
    <inertial>
      <origin
        xyz="0 0 0"
        rpy="0 0 0" />
      <mass
        value="578" />
      <inertia
        ixx="145.63"
        ixy="-71.36"
        ixz="26.86"
        iyy="776.5"
        iyz="5.58"
        izz="810.32" />
    </inertial>
    <visual>
      <origin
        xyz="0 0 0"
        rpy="0 0 0" />
      <geometry>
        <mesh
          filename="package://auto_tractor/meshes/Rear_left.STL" />
      </geometry>
      <material
        name="">
        <color
          rgba="0.61961 0.83137 0.81961 1" />
      </material>
    </visual>
    <collision>
      <origin
        xyz="0 0 0"
        rpy="0 0 0" />
      <geometry>
        <mesh
          filename="package://auto_tractor/meshes/Rear_left.STL" />
      </geometry>
    </collision>
  </link>

  <joint
    name="RL"
    type="continuous">
    <origin
      xyz="-1.3427 -0.8025 -0.10985"
      rpy="0 0 0" />
    <parent
      link="base_link" />
    <child
      link="Rear_left" />
    <axis
      xyz="0 1 0" />
  </joint>


<!-- Rear Right Wheel -->

  <link
    name="Rear_right">
    <inertial>
      <origin
        xyz="0 0 0"
        rpy="0 0 0" />
      <mass
        value="578" />
      <inertia
        ixx="145.63"
        ixy="-71.36"
        ixz="26.86"
        iyy="776.5"
        iyz="5.58"
        izz="810.32" />
    </inertial>
    <visual>
      <origin
        xyz="0 0 0"
        rpy="0 0 0" />
      <geometry>
        <mesh
          filename="package://auto_tractor/meshes/Rear_right.STL" />
      </geometry>
      <material
        name="">
        <color
          rgba="0.79216 0.81961 0.93333 1" />
      </material>
    </visual>
    <collision>
      <origin
        xyz="0 0 0"
        rpy="0 0 0" />
      <geometry>
        <mesh
          filename="package://auto_tractor/meshes/Rear_right.STL" />
      </geometry>
    </collision>
  </link>

  <joint
    name="RR"
    type="continuous">
    <origin
      xyz="-1.3427 0.8025 -0.10985"
      rpy="0 0 0" />
    <parent
      link="base_link" />
    <child
      link="Rear_right" />
    <axis
      xyz="0 1 0" />
  </joint>


  <!--Left Steering-->
  <joint name="front_left_steering_joint" type="revolute">
    <parent link="base_link"/>
    <child link="front_left_steering_link"/>
    <origin rpy="0 0 0" xyz="0.92106 -0.77764 -0.29107"/>
    <axis xyz="0 0 1"/>
    <limit effort="10000" lower="-0.6" upper="0.6" velocity="1000"/>
  </joint>

  <link name="front_left_steering_link">
    <parent link="base_link"/>
    <collision>
      <origin rpy="1.57079634179 0 0" xyz="0 0 0"/>
      <geometry>
        <cylinder length="0.05" radius="0.1"/>
      </geometry>
    </collision>
    <visual>
      <origin rpy="1.57079634179 0 0" xyz="0 0 0"/>
      <geometry>
        <cylinder length="0.05" radius="0.1"/>
      </geometry>
    </visual>
    <inertial>
      <origin rpy="0 0 0" xyz="0 0 0"/>
      <mass value="50.0"/>
      <inertia ixx="0.25" ixy="0.000000" ixz="0.000000" iyy="0.135416666667" iyz="0.000000" izz="0.135416666667"/>
    </inertial>
  </link>

  <!--Right Steering-->
  <joint name="front_right_steering_joint" type="revolute">
    <parent link="base_link"/>
    <child link="front_right_steering_link"/>
    <origin rpy="0 0 0" xyz="0.92106 0.77764 -0.29107"/>
    <axis xyz="0 0 1"/>
    <limit effort="10000" lower="-0.6" upper="0.6" velocity="1000"/>
  </joint>
  
  <link name="front_right_steering_link">
    <collision>
      <origin rpy="1.57079634179 0 0" xyz="0 0 0"/>
      <geometry>
        <cylinder length="0.05" radius="0.1"/>
      </geometry>
    </collision>
    <visual>
      <origin rpy="1.57079634179 0 0" xyz="0 0 0"/>
      <geometry>
        <cylinder length="0.05" radius="0.1"/>
      </geometry>
    </visual>
    <inertial>
      <origin rpy="0 0 0" xyz="0 0 0"/>
      <mass value="50.0"/>
      <inertia ixx="0.25" ixy="0.000000" ixz="0.000000" iyy="0.135416666667" iyz="0.000000" izz="0.135416666667"/>
    </inertial>
  </link>


  <!-- <gazebo reference="base_link">
    <material>Gazebo/Blue</material>
  </gazebo>
  
  <gazebo reference="Front_left">
    <material>Gazebo/Black</material>
  </gazebo>
  
  <gazebo reference="Front_right">
    <material>Gazebo/Black</material>
  </gazebo>

  <gazebo reference="Rear_right">
    <material>Gazebo/Black</material>
  </gazebo>
  
  <gazebo reference="Rear_left">
    <material>Gazebo/Black</material>
  </gazebo> -->
     
  <link name="ultrasonic_link">
    <visual>
      <geometry>
        <cylinder length="0.02" radius="0.01"/>
      </geometry>
      <material name="Gray"/>
    </visual>

    <collision>
      <geometry>
        <cylinder length="0.02" radius="0.01"/>
      </geometry>
    </collision>

    <inertial>
      <mass value="0.01"/>
      <origin xyz="0 0 0" rpy="0 0 0"/>
      <inertia ixx="0.000001" ixy="0" iyy="0.000001" izz="0.000001" iyz="0" ixz="0"/>
    </inertial>
  </link>

  <joint name="ultrasonic_joint" type="fixed">
    <parent link="base_link"/>
    <child link="ultrasonic_link"/>
    <origin xyz="0 0 0" rpy="0 0 0"/>
  </joint>


<!-- Front Left Ultrasonic Sensor -->

  <!-- <gazebo reference="ultrasonic_link">
    <sensor type="ray" name="ultrasonic_fl">
      <always_on>true</always_on>
      <update_rate>20</update_rate>
      <pose>1.386 -0.15525 0.62525 0 0 -0.65079</pose>
      <visualize>true</visualize>
      <ray>
        <scan>
          <horizontal>
            <samples>70</samples>
            <resolution>1</resolution>
            <min_angle>-1.22173</min_angle>
            <max_angle>1.22173</max_angle>
          </horizontal>
          <vertical>
            <samples>35</samples>
            <resolution>1</resolution>
            <min_angle>-0.610865</min_angle>
            <max_angle>0.610865</max_angle>
          </vertical>
        </scan>
        <range>
          <min>0.2</min>
          <max>2.5</max>
          <resolution>0.02</resolution>
        </range>
      </ray>

      <plugin name="ultrasonic_fl" filename="libhector_gazebo_ros_sonar.so">
        <gaussianNoise>0.005</gaussianNoise>
        <topicName>ultrasonic_fl</topicName>
        <frameId>ultrasonic_link</frameId>
      </plugin>
    </sensor>
  </gazebo> -->


<!-- Front Right Ultrasonic Sensor -->

  <!-- <gazebo reference="ultrasonic_link">
    <sensor type="ray" name="ultrasonic_fr">
      <always_on>true</always_on>
      <update_rate>20</update_rate>
      <pose>1.386 0.15525 0.62525 0 0 0.65079</pose>
      <visualize>true</visualize>
      <ray>
        <scan>
          <horizontal>
            <samples>70</samples>
            <resolution>1</resolution>
            <min_angle>-1.22173</min_angle>
            <max_angle>1.22173</max_angle>
          </horizontal>
          <vertical>
            <samples>35</samples>
            <resolution>1</resolution>
            <min_angle>-0.610865</min_angle>
            <max_angle>0.610865</max_angle>
          </vertical>
        </scan>
        <range>
          <min>0.2</min>
          <max>2.5</max>
          <resolution>0.02</resolution>
        </range>
      </ray>

      <plugin name="ultrasonic_fr" filename="libhector_gazebo_ros_sonar.so">
        <gaussianNoise>0.005</gaussianNoise>
        <topicName>ultrasonic_fr</topicName>
        <frameId>ultrasonic_link</frameId>
      </plugin>
    </sensor>
  </gazebo> -->


<!-- Middle Left Ultrasonic Sensor -->

  <!-- <gazebo reference="ultrasonic_link">
    <sensor type="ray" name="ultrasonic_ml">
      <always_on>true</always_on>
      <update_rate>20</update_rate>
      <pose>0.57286 -0.3473 0.638 0 0 -1.5708</pose>
      <visualize>true</visualize>
      <ray>
        <scan>
          <horizontal>
            <samples>70</samples>
            <resolution>1</resolution>
            <min_angle>-1.22173</min_angle>
            <max_angle>1.22173</max_angle>
          </horizontal>
          <vertical>
            <samples>35</samples>
            <resolution>1</resolution>
            <min_angle>-0.610865</min_angle>
            <max_angle>0.610865</max_angle>
          </vertical>
        </scan>
        <range>
          <min>0.2</min>
          <max>2.5</max>
          <resolution>0.02</resolution>
        </range>
      </ray>

      <plugin name="ultrasonic_ml" filename="libhector_gazebo_ros_sonar.so">
        <gaussianNoise>0.005</gaussianNoise>
        <topicName>ultrasonic_ml</topicName>
        <frameId>ultrasonic_link</frameId>
      </plugin>
    </sensor>
  </gazebo> -->


<!-- Middle Right Ultrasonic Sensor -->

  <!-- <gazebo reference="ultrasonic_link">
    <sensor type="ray" name="ultrasonic_mr">
      <always_on>true</always_on>
      <update_rate>20</update_rate>
      <pose>0.57286 0.3473 0.638 0 0 1.5708</pose>
      <visualize>true</visualize>
      <ray>
        <scan>
          <horizontal>
            <samples>70</samples>
            <resolution>1</resolution>
            <min_angle>-1.22173</min_angle>
            <max_angle>1.22173</max_angle>
          </horizontal>
          <vertical>
            <samples>35</samples>
            <resolution>1</resolution>
            <min_angle>-0.610865</min_angle>
            <max_angle>0.610865</max_angle>
          </vertical>
        </scan>
        <range>
          <min>0.2</min>
          <max>2.5</max>
          <resolution>0.02</resolution>
        </range>
      </ray>

      <plugin name="ultrasonic_mr" filename="libhector_gazebo_ros_sonar.so">
        <gaussianNoise>0.005</gaussianNoise>
        <topicName>ultrasonic_mr</topicName>
        <frameId>ultrasonic_link</frameId>
      </plugin>
    </sensor>
  </gazebo> -->
  
  <gazebo>
    <plugin name="gazebo_ros_control" filename="libgazebo_ros_control.so"/>
  </gazebo>


  <transmission name="rl_trans">
    <type>transmission_interface/SimpleTransmission</type>
    <joint name="RL">
      <hardwareInterface>hardware_interface/EffortJointInterface</hardwareInterface>
    </joint>
    <actuator name="rl_motor">
      <hardwareInterface>hardware_interface/EffortJointInterface</hardwareInterface>
      <mechanicalReduction>1</mechanicalReduction>
    </actuator>
  </transmission>

  <transmission name="rr_trans">
    <type>transmission_interface/SimpleTransmission</type>
    <joint name="RR">
      <hardwareInterface>hardware_interface/EffortJointInterface</hardwareInterface>
    </joint>
    <actuator name="rr_motor">
      <hardwareInterface>hardware_interface/EffortJointInterface</hardwareInterface>
      <mechanicalReduction>1</mechanicalReduction>
    </actuator>
  </transmission>

  <transmission name="left_steering">
    <type>transmission_interface/SimpleTransmission</type>
    <joint name="front_left_steering_joint">
      <hardwareInterface>hardware_interface/PositionJointInterface</hardwareInterface>
    </joint>
    <actuator name="eps_left">
      <hardwareInterface>hardware_interface/PositionJointInterface</hardwareInterface>
      <mechanicalReduction>1</mechanicalReduction>
    </actuator>
  </transmission>

  <transmission name="right_steering">
    <type>transmission_interface/SimpleTransmission</type>
    <joint name="front_right_steering_joint">
      <hardwareInterface>hardware_interface/PositionJointInterface</hardwareInterface>
    </joint>
    <actuator name="eps_right">
      <hardwareInterface>hardware_interface/PositionJointInterface</hardwareInterface>
      <mechanicalReduction>1</mechanicalReduction>
    </actuator>
  </transmission>
</robot>
